Traceback (most recent call last):
  File "C:\Users\WELCOME\AppData\Local\Programs\Python\Python313\Lib\site-packages\nbclient\client.py", line 782, in _async_poll_for_reply
    msg = await ensure_async(self.kc.shell_channel.get_msg(timeout=new_timeout))
          ^^^^^^^^^^^^^^^^^^^^^^^^^^^^^^^^^^^^^^^^^^^^^^^^^^^^^^^^^^^^^^^^^^^^^^
  File "C:\Users\WELCOME\AppData\Local\Programs\Python\Python313\Lib\site-packages\jupyter_core\utils\__init__.py", line 198, in ensure_async
    result = await obj
             ^^^^^^^^^
  File "C:\Users\WELCOME\AppData\Local\Programs\Python\Python313\Lib\site-packages\jupyter_client\channels.py", line 313, in get_msg
    raise Empty
_queue.Empty

During handling of the above exception, another exception occurred:

Traceback (most recent call last):
  File "C:\Users\WELCOME\AppData\Local\Programs\Python\Python313\Lib\site-packages\jupyter_cache\executors\utils.py", line 58, in single_nb_execution
    executenb(
    ~~~~~~~~~^
        nb,
        ^^^
    ...<4 lines>...
        **kwargs,
        ^^^^^^^^^
    )
    ^
  File "C:\Users\WELCOME\AppData\Local\Programs\Python\Python313\Lib\site-packages\nbclient\client.py", line 1319, in execute
    return NotebookClient(nb=nb, resources=resources, km=km, **kwargs).execute()
           ~~~~~~~~~~~~~~~~~~~~~~~~~~~~~~~~~~~~~~~~~~~~~~~~~~~~~~~~~~~~~~~~~~~^^
  File "C:\Users\WELCOME\AppData\Local\Programs\Python\Python313\Lib\site-packages\jupyter_core\utils\__init__.py", line 165, in wrapped
    return loop.run_until_complete(inner)
           ~~~~~~~~~~~~~~~~~~~~~~~^^^^^^^
  File "C:\Users\WELCOME\AppData\Local\Programs\Python\Python313\Lib\asyncio\base_events.py", line 720, in run_until_complete
    return future.result()
           ~~~~~~~~~~~~~^^
  File "C:\Users\WELCOME\AppData\Local\Programs\Python\Python313\Lib\site-packages\nbclient\client.py", line 709, in async_execute
    await self.async_execute_cell(
        cell, index, execution_count=self.code_cells_executed + 1
    )
  File "C:\Users\WELCOME\AppData\Local\Programs\Python\Python313\Lib\site-packages\nbclient\client.py", line 1005, in async_execute_cell
    exec_reply = await self.task_poll_for_reply
                 ^^^^^^^^^^^^^^^^^^^^^^^^^^^^^^
  File "C:\Users\WELCOME\AppData\Local\Programs\Python\Python313\Lib\site-packages\nbclient\client.py", line 806, in _async_poll_for_reply
    error_on_timeout_execute_reply = await self._async_handle_timeout(timeout, cell)
                                     ^^^^^^^^^^^^^^^^^^^^^^^^^^^^^^^^^^^^^^^^^^^^^^^
  File "C:\Users\WELCOME\AppData\Local\Programs\Python\Python313\Lib\site-packages\nbclient\client.py", line 856, in _async_handle_timeout
    raise CellTimeoutError.error_from_timeout_and_cell(
        "Cell execution timed out", timeout, cell
    )
nbclient.exceptions.CellTimeoutError: A cell timed out while it was being executed, after 30 seconds.
The message was: Cell execution timed out.
Here is a preview of the cell contents:
-------------------
['import os', 'import mlflow', 'from dagshub import DAGsHubLogger', 'import numpy as np', 'import pandas as pd']
...
['            mlflow.log_params(classifier.get_params())', '        ', '        print(f"Classifier: {classifier_name}")', '        print(f"Mean F1-Score (CV): {mean_f1:.4f} Â± {std_f1:.4f}")', '        print(f"Confusion Matrix: TP={tp}, TN={tn}, FP={fp}, FN={fn}")']
-------------------

